<?xml version="1.0"?>
<robot xmlns:xacro="http://www.ros.org/wiki/xacro">

    <xacro:include filename="colours.xacro" />
    <xacro:include filename="inertial_macros.xacro" />
    
    <!-- BASE LINK -->
    <link name="base_link"> 
    </link>

    <!-- CHASSIS -->
    <joint name = "chassis_joint" type= "fixed"> 
        <parent link = "base_link"/>
        <child link = "chassis_link"/>
        <origin xyz = "0 0 1"/>
    </joint>
    
    
    <link name = "chassis_link">
        <visual>
            <origin xyz = "0 0 0"/>
            <geometry>
                <box size = "4 2.46 0.1"/>
            </geometry>
            <material name ="gray"/>
        </visual>
        <collision>
            <origin xyz = "0 0 0"/>
            <geometry>
                <box size = "4 2.46 0.1"/>
            </geometry>
        </collision>
        <xacro:inertial_box mass="1" x="4" y="2.46" z="0.1">
            <origin xyz="0 0 0" rpy="-${pi/2} 0 0"/>
        </xacro:inertial_box>
    </link>

    <gazebo reference = "chassis_link">
        <material> Gazebo/Red </material>
    </gazebo>

    <!-- right square -->
    <joint name = "r_s_joint" type= "fixed"> 
        <parent link = "base_link"/>
        <child link = "r_s_link"/>
        <origin xyz = "0 0 0" rpy="-${pi/2} 0 0"/>
    </joint>
    
    
    <link name = "r_s_link">
        <visual>
            <origin xyz = "0 -1.5 -1.23"/>
            <geometry>
                <box size = "1 1 0.1"/>
            </geometry>
            <material name ="gray"/>
        </visual>
        <collision>
            <origin xyz = "0 -1.5 -1.23"/>
            <geometry>
                <box size = "1 1 0.1"/>
            </geometry>
        </collision>
        <xacro:inertial_box mass="1" x="1" y="1" z="0.1">
            <origin xyz="0 0 0" rpy="-${pi/2} 0 0"/>
        </xacro:inertial_box>
    </link>

    <gazebo reference = "r_s_link">
        <material> Gazebo/Red </material>
    </gazebo>

    <!-- left square -->
    <joint name = "l_s_joint" type= "fixed"> 
        <parent link = "base_link"/>
        <child link = "l_s_link"/>
        <origin xyz = "0 0 0" rpy="-${pi/2} 0 0"/>
    </joint>
    
    
    <link name = "l_s_link">
        <visual>
            <origin xyz = "0 -1.5 1.23"/>
            <geometry>
                <box size = "1 1 0.1"/>
            </geometry>
            <material name ="gray"/>
        </visual>
        <collision>
            <origin xyz = "0 -1.5 -1.23"/>
            <geometry>
                <box size = "1 1 0.1"/>
            </geometry>
        </collision>
        <xacro:inertial_box mass="1" x="1" y="1" z="0.1">
            <origin xyz="0 0 0" rpy="-${pi/2} 0 0"/>
        </xacro:inertial_box>
    </link>

    <gazebo reference = "l_s_link">
        <material> Gazebo/Red </material>
    </gazebo>
    
    <!--Camera joint-->
    <joint name= "camera_joint" type= "fixed">
    	<parent link ="base_link"/>
    	<child link= "camera_link"/>
    	<origin xyz="0 0 2"/>
    </joint>
    
    <link name="camera_link">
    	<visual>
    	    <origin xyz="2 0 0.05"/>
    	    <geometry>
    	    	<box size ="0.1 0.1 2"/>
    	    </geometry>
    	    <material name="white"/>
    	</visual>
    	<collision>
    	    <origin xyz="2 0 0.05"/>
    	    <geometry>
    	    	<box size ="0.1 0.1 2"/>
    	    </geometry>
    	    <material name="white"/>
    	</collision>
    	<xacro:inertial_box mass ="1" x="0.1" y="0.1" z="2">
    		<origin xyz="0 2 0" rpy="0 0 0"/>
    	</xacro:inertial_box>
    </link>
    <gazebo reference= "camera_link">
    	<material> Gazebo/White</material>
    </gazebo>

    <!--middle up joint-->
    <joint name= "mi_up_joint" type= "fixed">
    	<parent link ="base_link"/>
    	<child link= "mi_up_link"/>
    	<origin xyz="0 0 2"/>
    </joint>
    
    <link name="mi_up_link">
    	<visual>
    	    <origin xyz="0 0 -0.5"/>
    	    <geometry>
    	    	<box size ="0.1 2.46 0.1"/>
    	    </geometry>
    	    <material name="white"/>
    	</visual>
    	<collision>
    	    <origin xyz="0 0 -0.5"/>
    	    <geometry>
    	    	<box size ="0.1 2.46 0.1"/>
    	    </geometry>
    	    <material name="white"/>
    	</collision>
    	<xacro:inertial_box mass ="1" x="0.1" y="2.46" z="0.1">
    		<origin xyz="0 2 0" rpy="0 0 0"/>
    	</xacro:inertial_box>
    </link>
    <gazebo reference= "mi_up_link">
    	<material> Gazebo/White</material>
    </gazebo>

    <!--middle down joint-->
    <joint name= "mi_down_joint" type= "fixed">
    	<parent link ="base_link"/>
    	<child link= "mi_down_link"/>
    	<origin xyz="0 0 2"/>
    </joint>
    
    <link name="mi_down_link">
    	<visual>
    	    <origin xyz="0 0 -0.85"/>
    	    <geometry>
    	    	<box size ="0.1 2.46 0.1"/>
    	    </geometry>
    	    <material name="white"/>
    	</visual>
    	<collision>
    	    <origin xyz="0 0 -0.85"/>
    	    <geometry>
    	    	<box size ="0.1 2.46 0.1"/>
    	    </geometry>
    	    <material name="white"/>
    	</collision>
    	<xacro:inertial_box mass ="1" x="0.1" y="2.46" z="0.1">
    		<origin xyz="0 2 0" rpy="0 0 0"/>
    	</xacro:inertial_box>
    </link>
    <gazebo reference= "mi_down_link">
    	<material> Gazebo/White</material>
    </gazebo>

    <!--front left joint-->
    <joint name= "fl_joint" type= "fixed">
    	<parent link ="base_link"/>
    	<child link= "fl_link"/>
    	<origin xyz="0 0 1"/>
    </joint>
    
    <link name="fl_link">
    	<visual>
    	    <origin xyz="2 1.23 0.525"/>
    	    <geometry>
    	    	<box size ="0.1 0.1 1"/>
    	    </geometry>
    	    <material name="white"/>
    	</visual>
    	<collision>
    	    <origin xyz="2 1.23 0.525"/>
    	    <geometry>
    	    	<box size ="0.1 0.1 1"/>
    	    </geometry>
    	    <material name="white"/>
    	</collision>
    	<xacro:inertial_box mass ="1" x="0.1" y="0.1" z="1">
    		<origin xyz="2 1.23 0" rpy="0 0 0"/>
    	</xacro:inertial_box>
    </link>
    <gazebo reference= "fl_link">
    	<material> Gazebo/White</material>
    </gazebo>

    <!--front right joint-->
    <joint name= "fr_joint" type= "fixed">
    	<parent link ="base_link"/>
    	<child link= "fr_link"/>
    	<origin xyz="0 0 1"/>
    </joint>
    
    <link name="fr_link">
    	<visual>
    	    <origin xyz="2 -1.23 0.525"/>
    	    <geometry>
    	    	<box size ="0.1 0.1 1"/>
    	    </geometry>
    	    <material name="white"/>
    	</visual>
    	<collision>
    	    <origin xyz="2 1.23 0.525"/>
    	    <geometry>
    	    	<box size ="0.1 0.1 1"/>
    	    </geometry>
    	    <material name="white"/>
    	</collision>
    	<xacro:inertial_box mass ="1" x="0.1" y="0.1" z="1">
    		<origin xyz="-1.23 2 0" rpy="0 0 0"/>
    	</xacro:inertial_box>
    </link>
    <gazebo reference= "fr_link">
    	<material> Gazebo/White</material>
    </gazebo>

    <!--back left joint-->
    <joint name= "bl_joint" type= "fixed">
    	<parent link ="base_link"/>
    	<child link= "bl_link"/>
    	<origin xyz="0 0 1"/>
    </joint>
    
    <link name="bl_link">
    	<visual>
    	    <origin xyz="-2 1.23 0.525"/>
    	    <geometry>
    	    	<box size ="0.1 0.1 1"/>
    	    </geometry>
    	    <material name="white"/>
    	</visual>
    	<collision>
    	    <origin xyz="-2 1.23 0.525"/>
    	    <geometry>
    	    	<box size ="0.1 0.1 1"/>
    	    </geometry>
    	    <material name="white"/>
    	</collision>
    	<xacro:inertial_box mass ="1" x="0.1" y="0.1" z="1">
    		<origin xyz="1.23 -2 0" rpy="0 0 0"/>
    	</xacro:inertial_box>
    </link>
    <gazebo reference= "bl_link">
    	<material> Gazebo/White</material>
    </gazebo>

    <!--back middle joint-->
    <joint name= "bm_joint" type= "fixed">
    	<parent link ="base_link"/>
    	<child link= "bm_link"/>
    	<origin xyz="0 0 1"/>
    </joint>
    
    <link name="bm_link">
    	<visual>
    	    <origin xyz="-2 0 0.525"/>
    	    <geometry>
    	    	<box size ="0.1 0.1 1"/>
    	    </geometry>
    	    <material name="white"/>
    	</visual>
    	<collision>
    	    <origin xyz="-2 0 0.525"/>
    	    <geometry>
    	    	<box size ="0.1 0.1 1"/>
    	    </geometry>
    	    <material name="white"/>
    	</collision>
    	<xacro:inertial_box mass ="1" x="0.1" y="0.1" z="1">
    		<origin xyz="0 -2 0" rpy="0 0 0"/>
    	</xacro:inertial_box>
    </link>
    <gazebo reference= "bm_link">
    	<material> Gazebo/White</material>
    </gazebo>

    <!--back right joint-->
    <joint name= "br_joint" type= "fixed">
    	<parent link ="base_link"/>
    	<child link= "br_link"/>
    	<origin xyz="0 0 1"/>
    </joint>
    
    <link name="br_link">
    	<visual>
    	    <origin xyz="-2 -1.23 0.525"/>
    	    <geometry>
    	    	<box size ="0.1 0.1 1"/>
    	    </geometry>
    	    <material name="white"/>
    	</visual>
    	<collision>
    	    <origin xyz="-2 -1.23 1.05"/>
    	    <geometry>
    	    	<box size ="0.1 0.1 1"/>
    	    </geometry>
    	    <material name="white"/>
    	</collision>
    	<xacro:inertial_box mass ="1" x="0.1" y="0.1" z="1">
    		<origin xyz="-1.23 -2 0" rpy="0 0 0"/>
    	</xacro:inertial_box>
    </link>
    <gazebo reference= "br_link">
    	<material> Gazebo/White</material>
    </gazebo>
    
    <!--front joint-->
    <joint name= "front_joint" type= "fixed">
    	<parent link ="base_link"/>
    	<child link= "front_link"/>
    	<origin xyz="2 0 1"/>
    </joint>
    
    <link name="front_link">
    	<visual>
    	    <origin xyz="0 0 0"/>
    	    <geometry>
    	    	<box size ="0.1 2.45 0.1"/>
    	    </geometry>
    	    <material name="white"/>
    	</visual>
    	<collision>
    	    <origin xyz="0 0 0"/>
    	    <geometry>
    	    	<box size ="0.1 2.46 0.1"/>
    	    </geometry>
    	    <material name="white"/>
    	</collision>
    	<xacro:inertial_box mass ="1" x="0.1" y="0.1" z="2.46">
    		<origin xyz="0 2 0" rpy="0 0 0"/>
    	</xacro:inertial_box>
    </link>
    <gazebo reference= "front_link">
    	<material> Gazebo/White</material>
    </gazebo>

    <!--front up joint-->
    <joint name= "f_up_joint" type= "fixed">
    	<parent link ="base_link"/>
    	<child link= "f_up_link"/>
    	<origin xyz="2 0 2"/>
    </joint>
    
    <link name="f_up_link">
    	<visual>
    	    <origin xyz="0 0 0"/>
    	    <geometry>
    	    	<box size ="0.1 2.46 0.1"/>
    	    </geometry>
    	    <material name="white"/>
    	</visual>
    	<collision>
    	    <origin xyz="0 0 0"/>
    	    <geometry>
    	    	<box size ="0.1 2.46 0.1"/>
    	    </geometry>
    	    <material name="white"/>
    	</collision>
    	<xacro:inertial_box mass ="1" x="0.1" y="0.1" z="2.46">
    		<origin xyz="0 2 0" rpy="0 0 0"/>
    	</xacro:inertial_box>
    </link>

    <gazebo reference= "f_up_link">
    	<material> Gazebo/White</material>
    </gazebo>

    <!--right up joint-->
    <joint name= "r_up_joint" type= "fixed">
    	<parent link ="base_link"/>
    	<child link= "r_up_link"/>
    	<origin xyz="0 1.23 2"/>
    </joint>
    
    <link name="r_up_link">
    	<visual>
    	    <origin xyz="0 0 0"/>
    	    <geometry>
    	    	<box size ="4 0.1 0.1"/>
    	    </geometry>
    	    <material name="white"/>
    	</visual>
    	<collision>
    	    <origin xyz="0 0 0"/>
    	    <geometry>
    	    	<box size ="4 0.1 0.1"/>
    	    </geometry>
    	    <material name="white"/>
    	</collision>
    	<xacro:inertial_box mass ="1" x="4" y="0.1" z="0.1">
    		<origin xyz="0 1.23 2" rpy="0 0 0"/>
    	</xacro:inertial_box>
    </link>
    <gazebo reference= "r_up_link">
    	<material> Gazebo/White</material>
    </gazebo>

    <!--right joint-->
    <joint name= "r_joint" type= "fixed">
    	<parent link ="base_link"/>
    	<child link= "r_link"/>
    	<origin xyz="0 1.23 1"/>
    </joint>
    
    <link name="r_link">
    	<visual>
    	    <origin xyz="0 0 0"/>
    	    <geometry>
    	    	<box size ="4 0.1 0.1"/>
    	    </geometry>
    	    <material name="white"/>
    	</visual>
    	<collision>
    	    <origin xyz="0 0 0"/>
    	    <geometry>
    	    	<box size ="4 0.1 0.1"/>
    	    </geometry>
    	    <material name="white"/>
    	</collision>
    	<xacro:inertial_box mass ="1" x="4" y="0.1" z="0.1">
    		<origin xyz="0 1.23 0" rpy="0 0 0"/>
    	</xacro:inertial_box>
    </link>
    <gazebo reference= "r_link">
    	<material> Gazebo/White</material>
    </gazebo>

<!--left up joint-->
    <joint name= "l_up_joint" type= "fixed">
    	<parent link ="base_link"/>
    	<child link= "l_up_link"/>
    	<origin xyz="0 -1.23 2"/>
    </joint>
    
    <link name="l_up_link">
    	<visual>
    	    <origin xyz="0 0 0"/>
    	    <geometry>
    	    	<box size ="4 0.1 0.1"/>
    	    </geometry>
    	    <material name="white"/>
    	</visual>
    	<collision>
    	    <origin xyz="0 0 0"/>
    	    <geometry>
    	    	<box size ="4 0.1 0.1"/>
    	    </geometry>
    	    <material name="white"/>
    	</collision>
    	<xacro:inertial_box mass ="1" x="4" y="0.1" z="0.1">
    		<origin xyz="0 -1.23 1" rpy="0 0 0"/>
    	</xacro:inertial_box>
    </link>
    <gazebo reference= "l_up_link">
    	<material> Gazebo/White</material>
    </gazebo>

    <!--left joint-->
    <joint name= "l_joint" type= "fixed">
    	<parent link ="base_link"/>
    	<child link= "l_link"/>
    	<origin xyz="0 -1.23 1"/>
    </joint>
    
    <link name="l_link">
    	<visual>
    	    <origin xyz="0 0 0"/>
    	    <geometry>
    	    	<box size ="4 0.1 0.1"/>
    	    </geometry>
    	    <material name="white"/>
    	</visual>
    	<collision>
    	    <origin xyz="0 0 0"/>
    	    <geometry>
    	    	<box size ="4 0.1 0.1"/>
    	    </geometry>
    	    <material name="white"/>
    	</collision>
    	<xacro:inertial_box mass ="1" x="4" y="0.1" z="0.1">
    		<origin xyz="0 -1.23 0" rpy="0 0 0"/>
    	</xacro:inertial_box>
    </link>
    <gazebo reference= "l_link">
    	<material> Gazebo/White</material>
    </gazebo>

<!--back joint-->
    <joint name= "back_joint" type= "fixed">
    	<parent link ="base_link"/>
    	<child link= "back_link"/>
    	<origin xyz="-2 0 1"/>
    </joint>
    
    <link name="back_link">
    	<visual>
    	    <origin xyz="0 0 0"/>
    	    <geometry>
    	    	<box size ="0.1 2.46 0.1"/>
    	    </geometry>
    	    <material name="white"/>
    	</visual>
    	<collision>
    	    <origin xyz="0 0 0"/>
    	    <geometry>
    	    	<box size ="0.1 2.46 0.1"/>
    	    </geometry>
    	    <material name="white"/>
    	</collision>
    	<xacro:inertial_box mass ="1" x="0.1" y="0.1" z="2.46">
    		<origin xyz="0 -2 0" rpy="0 0 0"/>
    	</xacro:inertial_box>
    </link>
    <gazebo reference= "back_link">
    	<material> Gazebo/White</material>
    </gazebo>
<!--back up joint-->
    <joint name= "b_up_joint" type= "fixed">
    	<parent link ="base_link"/>
    	<child link= "b_up_link"/>
    	<origin xyz="-2 0 2"/>
    </joint>

    <link name="b_up_link">
    	<visual>
    	    <origin xyz="0 0 0"/>
    	    <geometry>
    	    	<box size ="0.1 2.46 0.1"/>
    	    </geometry>
    	    <material name="white"/>
    	</visual>
    	<collision>
    	    <origin xyz="0 0 0"/>
    	    <geometry>
    	    	<box size ="0.1 2.46 0.1"/>
    	    </geometry>
    	    <material name="white"/>
    	</collision>
    	<xacro:inertial_box mass ="1" x="0.1" y="0.1" z="2.46">
    		<origin xyz="0 -2 0" rpy="0 0 0"/>
    	</xacro:inertial_box>
    </link>
    <gazebo reference= "b_up_link">
    	<material> Gazebo/White</material>
    </gazebo>

    <!--middle up joint-->
    <joint name= "m_up_joint" type= "fixed">
    	<parent link ="base_link"/>
    	<child link= "m_up_link"/>
    	<origin xyz="-0.5 0 2"/>
    </joint>

    <link name="m_up_link">
    	<visual>
    	    <origin xyz="0 0 0"/>
    	    <geometry>
    	    	<box size ="0.1 2.46 0.1"/>
    	    </geometry>
    	    <material name="white"/>
    	</visual>
    	<collision>
    	    <origin xyz="0 0 0"/>
    	    <geometry>
    	    	<box size ="0.1 2.46 0.1"/>
    	    </geometry>
    	    <material name="white"/>
    	</collision>
    	<xacro:inertial_box mass ="1" x="0.1" y="0.1" z="2.46">
    		<origin xyz="0 -0.5 0" rpy="0 0 0"/>
    	</xacro:inertial_box>
    </link>
    <gazebo reference= "m_up_link">
    	<material> Gazebo/White</material>
    </gazebo>

    <!--right back up joint-->
    <joint name= "rb_up_joint" type= "fixed">
    	<parent link ="b_up_link"/>
    	<child link= "rb_up_link"/>
    	<origin xyz="0 0.5 0"/>
    </joint>

    <link name="rb_up_link">
    	<visual>
    	    <origin xyz="0.75 0 0"/>
    	    <geometry>
    	    	<box size ="1.5 0.1 0.1"/>
    	    </geometry>
    	    <material name="white"/>
    	</visual>
    	<collision>
    	    <origin xyz="0.75 0 0"/>
    	    <geometry>
    	    	<box size ="1.5 0.1 0.1"/>
    	    </geometry>
    	    <material name="white"/>
    	</collision>
    	<xacro:inertial_box mass ="1" x="1.5" y="0.1" z="0.1">
    		<origin xyz="0 1.5 0" rpy="0 0 0"/>
    	</xacro:inertial_box>
    </link>

    <gazebo reference= "rb_up_link">
    	<material> Gazebo/White</material>
    </gazebo>

    <!--left back up joint-->
    <joint name= "lb_up_joint" type= "fixed">
    	<parent link ="b_up_link"/>
    	<child link= "lb_up_link"/>
    	<origin xyz="0 -0.5 0"/>
    </joint>

    <link name="lb_up_link">
    	<visual>
    	    <origin xyz="0.75 0 0"/>
    	    <geometry>
    	    	<box size ="1.5 0.1 0.1"/>
    	    </geometry>
    	    <material name="white"/>
    	</visual>
    	<collision>
    	    <origin xyz="0.75 0 0"/>
    	    <geometry>
    	    	<box size ="1.5 0.1 0.1"/>
    	    </geometry>
    	    <material name="white"/>
    	</collision>
    	<xacro:inertial_box mass ="1" x="1.5" y="0.1" z="0.1">
    		<origin xyz="0 1.5 0" rpy="0 0 0"/>
    	</xacro:inertial_box>
    </link>

    <gazebo reference= "lb_up_link">
    	<material> Gazebo/White</material>
    </gazebo>

    <!-- LEFT FRONT WHEEL-->
    <joint name = "lf_wheel_joint" type= "continuous">
        <parent link = "chassis_link"/>
        <child link = "lf_wheel_link"/>
        <origin xyz = "1.3 1.23 -1" rpy="-${pi/2} 0 0"/>
        <axis xyz = "0 0 0.5"/>
    </joint>

    <link name = "lf_wheel_link">
        <visual>
        <origin xyz="0.4 0 0"/>
            <geometry>
                <cylinder radius = "0.475" length="0.30"/>
            </geometry>
            <material name ="white"/>
        </visual>
        <collision>
            <geometry>
                <cylinder radius = "0.475" length="0.30"/>
            </geometry>
        </collision>
        <xacro:inertial_cylinder mass="1" length="0.30" radius="0.475">
            <origin xyz="0 0 0" rpy="0 0 0"/>
        </xacro:inertial_cylinder>
    </link>

    <gazebo reference = "lf_wheel_link">
        <material> Gazebo/White </material>
    </gazebo>

	<!--left front wheel joint-->
	<joint name = "lfj_wheel_joint" type= "fixed">
        <parent link = "chassis_link"/>
        <child link = "lfj_wheel_link"/>
        <origin xyz = "1.3 1.23 -2" rpy="-${pi/2} 0 0"/>
        <axis xyz = "0 0 0.5"/>
    </joint>

    <link name = "lfj_wheel_link">
        <visual>
			<origin xyz="0 -1.5 0" rpy="0 0 ${3*pi/4}"/>
            <geometry>
                <box size="0.1 1.4 0.1"/>
            </geometry>
            <material name ="white"/>
        </visual>
        <collision>
            <geometry>
                <box size="0.1 1.4 0.1"/>
            </geometry>
        </collision>
        <xacro:inertial_box mass="0.1" x="0.1" y="1.4" z="0.1">
            <origin xyz="0 0 0" rpy="0 0 0"/>
        </xacro:inertial_box>
    </link>

    <gazebo reference = "lfj_wheel_link">
        <material> Gazebo/White </material>
    </gazebo>


    <!-- RIGHT FRONT WHEEL-->
    <joint name = "rf_wheel_joint" type= "continuous">
        <parent link = "chassis_link"/>
        <child link = "rf_wheel_link"/>
        <origin xyz = "1.3 -1.23 -1" rpy="${pi/2} 0 0"/>
        <axis xyz = "0 0 -0.5"/>
    </joint>

    <link name = "rf_wheel_link">
        <visual>
        <origin xyz="0.4 0 0" />
            <geometry>
                <cylinder radius = "0.475" length="0.30"/>
            </geometry>
            <material name ="white"/>
        </visual>
        <collision>
            <geometry>
                <cylinder radius = "0.475" length="0.30"/>
            </geometry>
        </collision>
        <xacro:inertial_cylinder mass="1" length="0.30" radius="0.475">
            <origin xyz="0 0 0" rpy="0 0 0"/>
        </xacro:inertial_cylinder>
    </link>

    <gazebo reference = "rf_wheel_link">
        <material> Gazebo/White </material>
    </gazebo>

	<!--right front wheel joint-->
	<joint name = "rfj_wheel_joint" type= "fixed">
        <parent link = "base_link"/>
        <child link = "rfj_wheel_link"/>
        <origin xyz = "1.3 -1.23 0.5" rpy="0 ${3*pi/4} 0"/>
        <axis xyz = "0 0 -0.5"/>
    </joint>

    <link name = "rfj_wheel_link">
        <visual>
	    <origin xyz="0 0 0" rpy="0 0 0" />
            <geometry>
                <box size="0.1 0.1 1.4"/>
            </geometry>
            <material name ="white"/>
        </visual>
        <collision>
            <geometry>
                <box size="0.1 0.1 1"/>
            </geometry>
        </collision>
        <xacro:inertial_box mass="0.1" x="0.1" y="0.1" z="1.4">
            <origin xyz="0 0 0" rpy="0 0 0"/>
        </xacro:inertial_box>
    </link>

    <gazebo reference = "rfj_wheel_link">
        <material> Gazebo/White </material>
    </gazebo>
    
    
    <!-- LEFT MIDDLE WHEEL-->
    <joint name = "lm_wheel_joint" type= "continuous">
        <parent link = "chassis_link"/>
        <child link = "lm_wheel_link"/>
        <origin xyz = "0 1.23 -1" rpy="-${pi/2} 0 0"/>
        <axis xyz = "0 0 0.5"/>
    </joint>

    <link name = "lm_wheel_link">
        <visual>
            <geometry>
                <cylinder radius = "0.475" length="0.30"/>
            </geometry>
            <material name ="white"/>
        </visual>
        <collision>
            <geometry>
                <cylinder radius = "0.475" length="0.30"/>
            </geometry>
        </collision>
        <xacro:inertial_cylinder mass="0.1" length="0.30" radius="0.475">
            <origin xyz="0 0 0" rpy="0 0 0"/>
        </xacro:inertial_cylinder>
    </link>

    <gazebo reference = "lm_wheel_link">
        <material> Gazebo/White </material>
    </gazebo>

	<!--left middle wheel joint-->
	<joint name = "lmj_wheel_joint" type= "fixed">
        <parent link = "chassis_link"/>
        <child link = "lmj_wheel_link"/>
        <origin xyz = "0 1.23 -2" rpy="-${pi/2} 0 0"/>
        <axis xyz = "0 0 0.5"/>
    </joint>

    <link name = "lmj_wheel_link"> 
        <visual>
	<origin xyz="-0.3 -1.5 0" rpy="0 0 -${pi/3}"/>
            <geometry>
                <box size="0.1 1.4 0.1"/>
            </geometry>
            <material name ="white"/>
        </visual>
        <collision>
            <geometry>
                <box size="0.1 1.4 0.1"/>
            </geometry>
        </collision>
        <xacro:inertial_box mass="0.1" x="0.1" y="1.4" z="0.1">
            <origin xyz="0 0 0" rpy="0 0 0"/>
        </xacro:inertial_box>
    </link>

    <gazebo reference = "lmj_wheel_link">
        <material> Gazebo/White </material>
    </gazebo>
    
    
    <!-- RIGHT MIDDLE WHEEL-->
    <joint name = "rm_wheel_joint" type= "continuous">
        <parent link = "chassis_link"/>
        <child link = "rm_wheel_link"/>
        <origin xyz = "0 -1.23 -1" rpy="${pi/2} 0 0"/>
        <axis xyz = "0 0 -0.5"/>
    </joint>

    <link name = "rm_wheel_link">
        <visual>
            <geometry>
                <cylinder radius = "0.475" length="0.30"/>
            </geometry>
            <material name ="white"/>
        </visual>
        <collision>
            <geometry>
                <cylinder radius = "0.475" length="0.30"/>
            </geometry>
        </collision>
        <xacro:inertial_cylinder mass="0.1" length="0.30" radius="0.475">
            <origin xyz="0 0 0" rpy="0 0 0"/>
        </xacro:inertial_cylinder>
    </link>

    <gazebo reference = "rm_wheel_link">
        <material> Gazebo/White </material>
    </gazebo>

	<!--right middle wheel joint-->
    <joint name = "rmj_wheel_joint" type= "fixed">
        <parent link = "base_link"/>
        <child link = "rmj_wheel_link"/>
        <origin xyz = "-0.2 -1.23 0.5" rpy="0 0 0"/>
        <axis xyz = "0 0 -0.5"/>
    </joint>

    <link name = "rmj_wheel_link">
        <visual>
	    <origin xyz="0 0 0" rpy="0 -${pi/3} 0"/>
            <geometry>
                <box size="0.1 0.1 1.1"/>
            </geometry>
            <material name ="white"/>
        </visual>
        <collision>
            <geometry>
                <box size="0.1 0.1 1.1"/>
            </geometry>
        </collision>
        <xacro:inertial_box mass="0.1" x="0.1" y="0.1" z="1.1">
            <origin xyz="0 0 0" rpy="0 0 0"/>
        </xacro:inertial_box>
    </link>

    <gazebo reference = "rmj_wheel_link">
        <material> Gazebo/White </material>
    </gazebo>
    
    
    <!-- LEFT BACK WHEEL-->
    <joint name = "lb_wheel_joint" type= "continuous">
        <parent link = "chassis_link"/>
        <child link = "lb_wheel_link"/>
        <origin xyz = "-1.3 1.23 -1" rpy="-${pi/2} 0 0"/>
        <axis xyz = "0 0 0.5"/>
    </joint>

    <link name = "lb_wheel_link">
        <visual>
            <geometry>
                <cylinder radius = "0.475" length="0.30"/>
            </geometry>
            <material name ="white"/>
        </visual>
        <collision>
            <geometry>
                <cylinder radius = "0.475" length="0.30"/>
            </geometry>
        </collision>
        <xacro:inertial_cylinder mass="0.1" length="0.30" radius="0.475">
            <origin xyz="0 0 0" rpy="0 0 0"/>
        </xacro:inertial_cylinder>
    </link>

    <gazebo reference = "lb_wheel_link">
        <material> Gazebo/White </material>
    </gazebo>

	<!--left back wheel joint-->
	<joint name = "lbj_wheel_joint" type= "fixed">
        <parent link = "chassis_link"/>
        <child link = "lbj_wheel_link"/>
        <origin xyz = "-1.3 1.23 -2" rpy="-${pi/2} 0 0"/>
        <axis xyz = "0 0 0.5"/>
    </joint>

    <link name = "lbj_wheel_link">
        <visual>
		<origin xyz="0.1 -1.5 0" rpy="0 0 ${pi/4}"/>
            <geometry>
                <box size="0.1 1.4 0.1"/>
            </geometry>
            <material name ="white"/>
        </visual>
        <collision>
            <geometry>
                <box size="0.1 1.4 0.1"/>
            </geometry>
        </collision>
        <xacro:inertial_box mass="0.1" x="0.1" y="1.4" z="0.1">
            <origin xyz="0 0 0" rpy="0 0 0"/>
        </xacro:inertial_box>
    </link>

    <gazebo reference = "lbj_wheel_link">
        <material> Gazebo/White </material>
    </gazebo>

    <!-- RIGHT BACK WHEEL-->
    <joint name = "rb_wheel_joint" type= "continuous">
        <parent link = "chassis_link"/>
        <child link = "rb_wheel_link"/>
        <origin xyz = "-1.3 -1.23 -1" rpy="${pi/2} 0 0"/>
        <axis xyz = "0 0 -0.5"/>
    </joint>

    <link name = "rb_wheel_link">
        <visual>
            <geometry>
                <cylinder radius = "0.475" length="0.30"/>
            </geometry>
            <material name ="white"/>
        </visual>
        <collision>
            <geometry>
                <cylinder radius = "0.475" length="0.30"/>
            </geometry>
        </collision>
        <xacro:inertial_cylinder mass="0.1" length="0.30" radius="0.475">
            <origin xyz="0 0 0" rpy="0 0 0"/>
        </xacro:inertial_cylinder>
    </link>

    <gazebo reference = "rb_wheel_link">
        <material> Gazebo/White </material>
    </gazebo>

	<!--right back wheel joint-->
    <joint name = "rbj_wheel_joint" type= "fixed">
        <parent link = "base_link"/>
        <child link = "rbj_wheel_link"/>
        <origin xyz = "-1 -1.23 0.5" rpy="0 ${pi/4} 0"/>
        <axis xyz = "0 0 -0.5"/>
    </joint>

    <link name = "rbj_wheel_link">
        <visual>
	<origin xyz="0 0 0"/>
            <geometry>
                <box size="0.1 0.1 1.4"/>
            </geometry>
            <material name ="white"/>
        </visual>
        <collision>
            <geometry>
                <box size="0.1 0.1 1.4"/>
            </geometry>
        </collision>
        <xacro:inertial_box mass="0.1" x="0.1" y="0.1" z="1.5">
            <origin xyz="0 0 0" rpy="0 0 0"/>
        </xacro:inertial_box>
    </link>

    <gazebo reference = "rbj_wheel_link">
        <material> Gazebo/White </material>
    </gazebo>

</robot>
